<?xml version="1.0" encoding="utf-8"?>
<!-- This URDF was automatically created by SolidWorks to URDF Exporter! Originally created by Stephen Brawner (brawner@gmail.com) 
     Commit Version: 1.6.0-1-g15f4949  Build Version: 1.6.7594.29634
     For more information, please see http://wiki.ros.org/sw_urdf_exporter -->
<robot
  name="urdf-head">
  <!-- this link makes the robot fixed-base in RAISIM -->
  <link name="world"></link>

  <link name="base_link">
    <!-- edited with custom script -->
    <inertial>
      <origin 
        xyz="-0.00013000000000000002 5.9999999999999995e-05 -0.019559999999999998"
        rpy="0 0 0" />
      <mass
        value="0.22691" />
      <inertia
        ixx="6.726675999999999e-05"
        ixy="-2.4361e-07"
        ixz="-6.3156e-07"
        iyy="6.666816e-05"
        iyz="6.418000000000001e-08"
        izz="7.244472e-05" />
    </inertial>
    <visual>
      <origin
        xyz="0 0 0"
        rpy="0 0 0" />
      <geometry>
        <mesh
          filename="package://urdf-head/meshes/base_link.STL" />
      </geometry>
      <material
        name="">
        <color
          rgba="0.898039215686275 0.917647058823529 0.929411764705882 1" />
      </material>
    </visual>
    <!-- <collision>
      <origin
        xyz="0 0 0"
        rpy="0 0 0" />
      <geometry>
        <mesh
          filename="package://urdf-head/meshes/base_link.STL" />
      </geometry>
    </collision> -->
  </link>

  <joint name="base_world" type="fixed">
    <origin xyz="0 0 0" rpy="0 0 0"/>
    <parent link="world" />
    <child link="base_link" />
    <axis xyz="0 0 0" />
  </joint>

  <link name="neck">
    <!-- edited with custom script -->
    <inertial>
    <origin
        xyz="-0.00621 -0.0005899999999999999 0.09247"
        rpy="0 0 0" />
    <mass
        value="0.38718" />
    <inertia
        ixx="0.00084209162"
        ixy="1.78477e-06"
        ixz="-3.73364e-06"
        iyy="0.00090124031"
        iyz="6.43932e-06"
        izz="0.00015094396" />
    </inertial>
    <visual>
      <origin
        xyz="0 0 0"
        rpy="0 0 0" />
      <geometry>
        <mesh
          filename="package://urdf-head/meshes/neck.STL" />
      </geometry>
      <material
        name="">
        <color
          rgba="0.898039215686275 0.917647058823529 0.929411764705882 1" />
      </material>
    </visual>
    <!-- <collision>
      <origin
        xyz="0 0 0"
        rpy="0 0 0" />
      <geometry>
        <mesh
          filename="package://urdf-head/meshes/neck.STL" />
      </geometry>
    </collision> -->
  </link>
  <joint name="pan"
    type="revolute">
    <origin
      xyz="0 0 0"
      rpy="0 0 0" />
    <parent
      link="base_link" />
    <child
      link="neck" />
    <axis
      xyz="0 0 -1" />
    <limit
      lower="-225"
      upper="225"
      effort="1.57"
      velocity="390" />
  </joint>
  <link name="chin">
    <!-- edited with custom script -->
    <inertial>
    <origin
        xyz="0.00292 -0.00883 -0.01141"
        rpy="0 0 0" />
    <mass
        value="0.06976" />
    <inertia
        ixx="4.2354910000000004e-05"
        ixy="-1.650247e-05"
        ixz="3.6080700000000003e-06"
        iyy="6.330044e-05"
        iyz="-3.7976999999999997e-07"
        izz="6.109326e-05" />
    </inertial>
    <visual>
      <origin
        xyz="0 0 0"
        rpy="0 0 0" />
      <geometry>
        <mesh
          filename="package://urdf-head/meshes/chin.STL" />
      </geometry>
      <material
        name="">
        <color
          rgba="0.752941176470588 0.752941176470588 0.752941176470588 1" />
      </material>
    </visual>
    <!-- <collision>
      <origin
        xyz="0 0 0"
        rpy="0 0 0" />
      <geometry>
        <mesh
          filename="package://urdf-head/meshes/chin.STL" />
      </geometry>
    </collision> -->
  </link>
  <joint name="tilt"
    type="revolute">
    <origin
      xyz="0 0.0186 0.12"
      rpy="-1.5708 0 0" />
    <parent
      link="neck" />
    <child
      link="chin" />
    <axis
      xyz="0 0 -1" />
    <limit
      lower="-1.0472"
      upper="0.83776"
      effort="1.57"
      velocity="390" />
  </joint>
  <link name="face">
    <!-- edited with custom script -->
    <inertial>
    <origin
        xyz="-0.011550000000000001 -0.02876 -0.01864"
        rpy="0 0 0" />
    <mass
        value="0.18813" />
    <inertia
        ixx="0.0006845556"
        ixy="-7.591147e-05"
        ixz="1.6041e-07"
        iyy="0.0010570050700000001"
        iyz="2.1684999999999999e-07"
        izz="0.00072350371" />
    </inertial>
    <visual>
      <origin
        xyz="0 0 0"
        rpy="0 0 0" />
      <geometry>
        <mesh
          filename="package://urdf-head/meshes/face.STL" />
      </geometry>
      <material
        name="">
        <color
          rgba="0.250980392156863 0.250980392156863 0.250980392156863 1" />
      </material>
    </visual>
    <!-- <collision>
      <origin
        xyz="0 0 0"
        rpy="0 0 0" />
      <geometry>
        <mesh
          filename="package://urdf-head/meshes/face.STL" />
      </geometry>
    </collision> -->
  </link>
  <joint name="chin_face"
    type="fixed">
    <origin
      xyz="0 0 0"
      rpy="0 0 0" />
    <parent
      link="chin" />
    <child
      link="face" />
    <axis
      xyz="0 0 0" />
  </joint>
  <link name="d455_link">
    <!-- edited with custom script -->
    <inertial>
    <origin
        xyz="0.01298 5e-05 -0.00014000000000000001"
        rpy="0 0 0" />
    <mass
        value="0.12" />
    <inertia
        ixx="0.00014290851000000002"
        ixy="3.955e-08"
        ixz="-1.4216e-07"
        iyy="1.328332e-05"
        iyz="6.73e-08"
        izz="0.00014208451" />
    </inertial>
    <visual>
      <origin
        xyz="0 0 0"
        rpy="0 0 0" />
      <geometry>
        <mesh
          filename="package://urdf-head/meshes/d455_link.STL" />
      </geometry>
      <material
        name="">
        <color
          rgba="0.792156862745098 0.819607843137255 0.933333333333333 1" />
      </material>
    </visual>
    <!-- <collision>
      <origin
        xyz="0 0 0"
        rpy="0 0 0" />
      <geometry>
        <mesh
          filename="package://urdf-head/meshes/d455_link.STL" />
      </geometry>
    </collision> -->
  </link>
  <joint name="chin_d455"
    type="fixed">
    <origin
      xyz="0.042 0 -0.0186"
      rpy="1.5708 0 0" />
    <parent
      link="chin" />
    <child
      link="d455_link" />
    <axis
      xyz="0 0 0" />
  </joint>
  <link name="mid360_link">
    <!-- edited with custom script -->
    <inertial>
    <origin
        xyz="-0.0002 -1e-05 0.02203"
        rpy="0 0 0" />
    <mass
        value="0.265" />
    <inertia
        ixx="0.00012374566"
        ixy="-1.1019999999999999e-08"
        ixz="-1.964e-08"
        iyy="0.00013334891"
        iyz="-3.4840000000000006e-08"
        izz="0.0001322739" />
    </inertial>
    <visual>
      <origin
        xyz="0 0 0"
        rpy="0 0 0" />
      <geometry>
        <mesh
          filename="package://urdf-head/meshes/mid360_link.STL" />
      </geometry>
      <material
        name="">
        <color
          rgba="0.792156862745098 0.819607843137255 0.933333333333333 1" />
      </material>
    </visual>
    <!-- <collision>
      <origin
        xyz="0 0 0"
        rpy="0 0 0" />
      <geometry>
        <mesh
          filename="package://urdf-head/meshes/mid360_link.STL" />
      </geometry>
    </collision> -->
  </link>
  <joint name="chin_mid360"
    type="fixed">
    <origin
      xyz="-0.025 -0.042 -0.0186"
      rpy="1.5708 0 0" />
    <parent
      link="chin" />
    <child
      link="mid360_link" />
    <axis
      xyz="0 0 0" />
  </joint>
</robot>